<?xml version="1.0"?>
<robot xmlns:xacro="http://www.ros.org/wiki/xacro">

    <material name="green">
        <color rgba="0 0.6 0 1" />
    </material>

    <material name="gray">
        <color rgba="0.7 0.7 0.7 1" />
    </material>

    <material name = "black">
        <color rgba="0 0 0 1"/>
    </material>

    <xacro:macro name="box_inertia" params="m x y z o_xyz o_rpy">
        <inertial>
            <mass value="${m}" />
            <origin xyz="${o_xyz}" rpy="${o_rpy}" />
            <inertia ixx="${(m/12) * (z*z + y*y)}" ixy="0" ixz="0"
                    iyy="${(m/12) * (x*x + z*z)}" iyz="0"
                    izz="${(m/12) * (x*x + y*y)}" />
        </inertial>
    </xacro:macro>

    <xacro:macro name="cylinder_inertia" params="m r l o_xyz o_rpy">
        <inertial>
            <mass value="${m}" />
            <origin xyz="${o_xyz}" rpy="${o_rpy}" />
            <inertia ixx="${(m/12) * (3*r*r + l*l)}" ixy="0" ixz="0"
                    iyy="${(m/12) * (3*r*r + l*l)}" iyz="0"
                    izz="${(m/2) * (r*r)}" />
        </inertial>
    </xacro:macro>

    <xacro:macro name="sphere_inertia" params="m r o_xyz o_rpy">
        <inertial>
            <mass value="${m}" />
            <origin xyz="${o_xyz}" rpy="${o_rpy}" />
            <inertia ixx="${(2/5) * m * r * r}" ixy="0" ixz="0"
                    iyy="${(2/5) * m * r * r}" iyz="0"
                    izz="${(2/5) * m * r * r}" />
        </inertial>
    </xacro:macro>

    <xacro:macro name="camera" params="width height hfov color">
        
    <visual>
        <geometry>
            <box size="0.015 0.040 0.030" />
        </geometry>
        <material name="${color}" />
        <origin xyz="0 0 0" rpy="0 0 0" />
    </visual>
    <visual>
        <geometry>
            <cylinder radius="0.010" length="0.015"/>
        </geometry>
        <material name="green" />
        <origin xyz="0.0075 0 0" rpy="0 ${pi / 2.0} 0" />
    </visual>
    <mass value = "0.1" />
        <inertia ixx="0.000166667" iyy = "0.000166667" izz="0.000166667" />
    </xacro:macro>
    
   <xacro:macro name="wheel_link" params="prefix">
        <link name="${prefix}_wheel_link">
            <visual>
                <geometry>
                    <cylinder radius="${wheel_radius}" length="${wheel_length}" />
                </geometry>
                <origin xyz="0 0 0" rpy="${pi / 2.0} 0 0" />
                <material name="gray" />
            </visual>
            <collision>
                <geometry>
                    <sphere radius="${wheel_radius}" />
                </geometry>
                <origin xyz="0 0 0" rpy="0 0 0" />
            </collision>
            <xacro:cylinder_inertia m="1.0" r="${wheel_radius}" l="${wheel_length}" 
                                    o_xyz="0 0 0" o_rpy="${pi / 2.0} 0 0" />
        </link>
    </xacro:macro>


    <xacro:macro name = "wheel_joint" params = "child_prefix xyz">
        <joint name="base_${child_prefix}_wheel_joint" type="continuous">
            <parent link="base_link" />
            <child link="${child_prefix}_wheel_link" />
            <origin xyz="${xyz}" rpy="0 0 0" />
            <axis xyz="0 1 0" />
        </joint>
    </xacro:macro>

</robot>